Workbook

Sheet Chicago Traffic Citations Data
A1: Notice Number | B1: Ticket Number | C1: Issue Date | D1: Violation Location | E1: Zip Code | F1: Violation Code | G1: Violation Description | H1: Unit | I1: Unit Description | J1: Officer | K1: Vehicle Make | L1: License Plate Type | M1: Fine Level 1 Amount | N1: Fine Level 2 Amount | O1: Current Amount Due | P1: Total Payments | Q1: Ticket Queue | R1: Ticket Queue Date | S1: Notice Level | T1: Hearing Dispo | U1: Hearing Reason
A2: 5201586250 | B2: 7009321333 | C2: 44197 | D2: 4200 S CICERO AVENUE | E2: 606234332 | F2: 9102020 | G2: RED LIGHT VIOLATION | H2: CNDT | I2: Red Light | J2: CNDT | K2: OTHR | L2: PAS | M2: 100 | N2: 200 | O2: 200 | P2: 0 | Q2: Notice | R2: 44210 | S2: SEIZ
A3: 5234871820 | B3: 7009321352 | C3: 44197 | D3: 1600 W 87TH ST | E3: 606331323 | F3: 9102020 | G3: RED LIGHT VIOLATION | H3: CNDT | I3: Red Light | J3: CNDT | K3: OTHR | L3: PAS | M3: 100 | N3: 200 | O3: 0 | P3: 200 | Q3: Paid | R3: 44291 | S3: FINL
A4: 5228076530 | B4: 72156572 | C4: 44197.001 | D4: 547 S COLUMBUS | E4: 606591649 | F4: 0964080B | G4: NO STANDING/PARKING TIME RESTRICTED | H4: 1 | I4: CPD | J4: 7861 | K4: BMW | L4: PAS | M4: 100 | N4: 200 | O4: 0 | P4: 100 | Q4: Paid | R4: 44217 | S4: VIOL
A5: 5233269710 | B5: 7009325236 | C5: 44197.001 | D5: 1 S WESTERN AVE | E5: 60623 | F5: 9102020 | G5: RED LIGHT VIOLATION | H5: CNDT | I5: Red Light | J5: CNDT | K5: OTHR | L5: PAS | M5: 100 | N5: 200 | O5: 200 | P5: 0 | Q5: Notice | R5: 44210 | S5: FINL
A6: 5219674400 | B6: 7009321372 | C6: 44197.001 | D6: 6700 S CORNELL DRIVE | E6: 606373598 | F6: 9102020 | G6: RED LIGHT VIOLATION | H6: CNDT | I6: Red Light | J6: CNDT | K6: OTHR | L6: PAS | M6: 100 | N6: 200 | O6: 200 | P6: 0 | Q6: Notice | R6: 44210 | S6: SEIZ
A7: 5199289380 | B7: 7009321329 | C7: 44197.001 | D7: 4400 W OGDEN AVENUE | E7: 60651 | F7: 9102020 | G7: RED LIGHT VIOLATION | H7: CNDT | I7: Red Light | J7: CNDT | K7: OTHR | L7: PAS | M7: 100 | N7: 200 | O7: 200 | P7: 0 | Q7: Notice | R7: 44210 | S7: SEIZ
A8: 5225329540 | B8: 7009321376 | C8: 44197.001 | D8: 300 S MICHIGAN AVE | E8: 604114539 | F8: 9102020 | G8: RED LIGHT VIOLATION | H8: CNDT | I8: Red Light | J8: CNDT | K8: OTHR | L8: PAS | M8: 100 | N8: 200 | O8: 0 | P8: 100 | Q8: Paid | R8: 44275 | S8: DETR
A9: 5212146160 | B9: 7009323424 | C9: 44197.001 | D9: 6300 S KEDZIE AVE | E9: 606094282 | F9: 9102020 | G9: RED LIGHT VIOLATION | H9: CNDT | I9: Red Light | J9: CNDT | K9: OTHR | L9: PAS | M9: 100 | N9: 200 | O9: 0 | P9: 100 | Q9: Paid | R9: 44234 | S9: VIOL
A10: 5235227160 | B10: 7009340321 | C10: 44197.002 | D10: 8700 S LAFAYETTE AVEN | E10: 60619 | F10: 9102020 | G10: RED LIGHT VIOLATION | H10: CNDT | I10: Red Light | J10: CNDT | K10: OTHR | L10: PAS | M10: 100 | N10: 200 | O10: 200 | P10: 0 | Q10: Notice | R10: 44228 | S10: FINL
A11: 5210709690 | B11: 7009321419 | C11: 44197.004 | D11: 400 S WESTERN AVENUE | E11: 601531403 | F11: 9102020 | G11: RED LIGHT VIOLATION | H11: CNDT | I11: Red Light | J11: CNDT | K11: OTHR | L11: PAS | M11: 100 | N11: 200 | O11: 200 | P11: 0 | Q11: Notice | R11: 44210 | S11: FINL
A12: 5231657240 | B12: 7009321728 | C12: 44197.005 | D12: 1600 W 87TH ST | E12: 60620 | F12: 9102020 | G12: RED LIGHT VIOLATION | H12: CNDT | I12: Red Light | J12: CNDT | K12: OTHR | L12: PAS | M12: 100 | N12: 200 | O12: 200 | P12: 0 | Q12: Notice | R12: 44210 | S12: FINL
A13: 5146642870 | B13: 72156573 | C13: 44197.006 | D13: 355 S COLUMBUS | E13: 605231607 | F13: 0964080B | G13: NO STANDING/PARKING TIME RESTRICTED | H13: 1 | I13: CPD | J13: 7861 | K13: LEXU | L13: PAS | M13: 100 | N13: 200 | O13: 0 | P13: 100 | Q13: Paid | R13: 44248 | S13: DETR
A14: 5182305720 | B14: 7009321379 | C14: 44197.006 | D14: 4000 W FOSTER AVE | E14: 600904517 | F14: 9102020 | G14: RED LIGHT VIOLATION | H14: CNDT | I14: Red Light | J14: CNDT | K14: OTHR | L14: PAS | M14: 100 | N14: 200 | O14: 0 | P14: 100 | Q14: Paid | R14: 44239 | S14: VIOL
A15: 5234898530 | B15: 7009323431 | C15: 44197.006 | D15: 2800 N CALIFORNIA AVE | E15: 604311528 | F15: 9102020 | G15: RED LIGHT VIOLATION | H15: CNDT | I15: Red Light | J15: CNDT | K15: OTHR | L15: PAS | M15: 100 | N15: 200 | O15: 0 | P15: 100 | Q15: Paid | R15: 44247 | S15: VIOL
A16: 5234898570 | B16: 7009323444 | C16: 44197.006 | D16: 4000 W NORTH AVENUE | E16: 60651 | F16: 9102020 | G16: RED LIGHT VIOLATION | H16: CNDT | I16: Red Light | J16: CNDT | K16: OTHR | L16: PAS | M16: 100 | N16: 200 | O16: 200 | P16: 0 | Q16: Notice | R16: 44210 | S16: FINL
A17: 5232016660 | B17: 71742149 | C17: 44197.007 | D17: 3228 N NAGLE | E17: 606293418 | F17: 0964100C | G17: BLOCK ACCESS/ALLEY/DRIVEWAY/FIRELANE | H17: 16 | I17: CPD | J17: 3051 | K17: TOYT | L17: PAS | M17: 150 | N17: 300 | O17: 0 | P17: 150 | Q17: Paid | R17: 44218 | S17: VIOL
A18: 5230434020 | B18: 7009323426 | C18: 44197.007 | D18: 800 W 119TH STREET | E18: 463076267 | F18: 9102020 | G18: RED LIGHT VIOLATION | H18: CNDT | I18: Red Light | J18: CNDT | K18: OTHR | L18: PAS | M18: 100 | N18: 200 | O18: 200 | P18: 0 | Q18: Notice | R18: 44210 | S18: SEIZ
A19: 0 | B19: 71627237 | C19: 44197.008 | D19: 1542 W BIRCHWOOD | F19: 0964100A | G19: WITHIN 15' OF FIRE HYDRANT | H19: 24 | I19: CPD | J19: 7540 | K19: CHEV | L19: TMP | M19: 150 | N19: 300 | O19: 150 | P19: 0 | Q19: Define | R19: 44207
A20: 5235085950 | B20: 7009321410 | C20: 44197.009 | D20: 100 W CHICAGO AVENUE | E20: 78240 | F20: 9102020 | G20: RED LIGHT VIOLATION | H20: CNDT | I20: Red Light | J20: CNDT | K20: OTHR | L20: PAS | M20: 100 | N20: 200 | O20: 0 | P20: 200 | Q20: Paid | R20: 44326 | S20: FINL
A21: 5235022390 | B21: 7009321378 | C21: 44197.01 | D21: 5930 N CLARK STREET | E21: 432302542 | F21: 9102020 | G21: RED LIGHT VIOLATION | H21: CNDT | I21: Red Light | J21: CNDT | K21: OTHR | L21: PAS | M21: 100 | N21: 200 | O21: 0 | P21: 100 | Q21: Paid | R21: 44238 | S21: VIOL
A22: 5183885050 | B22: 7009321744 | C22: 44197.01 | D22: 2400 N ASHLAND AVENUE | E22: 601758147 | F22: 9102020 | G22: RED LIGHT VIOLATION | H22: CNDT | I22: Red Light | J22: CNDT | K22: OTHR | L22: PAS | M22: 100 | N22: 200 | O22: 0 | P22: 100 | Q22: Paid | R22: 44242 | S22: VIOL
A23: 5234863210 | B23: 7009321363 | C23: 44197.01 | D23: 30 W 87TH STREET | E23: 37166 | F23: 9102020 | G23: RED LIGHT VIOLATION | H23: CNDT | I23: Red Light | J23: CNDT | K23: OTHR | L23: PAS | M23: 100 | N23: 200 | O23: 200 | P23: 0 | Q23: Notice | R23: 44223 | S23: FINL
A24: 5150213160 | B24: 71746964 | C24: 44197.01 | D24: 25 W HUBBARD | E24: 606321725 | F24: 0964080B | G24: NO STANDING/PARKING TIME RESTRICTED | H24: 495 | I24: Miscellaneous | J24: 494 | K24: HYUN | L24: PAS | M24: 100 | N24: 200 | O24: 200 | P24: 0 | Q24: Notice | R24: 44238 | S24: FINL
A25: 5232386800 | B25: 72154451 | C25: 44197.011 | D25: 79 E 8TH ST | E25: 609012772 | F25: 0964150B | G25: PARKING/STANDING PROHIBITED ANYTIME | H25: 1 | I25: CPD | J25: 9463 | K25: VOLK | L25: PAS | M25: 75 | N25: 150 | O25: 150 | P25: 0 | Q25: Notice | R25: 44210 | S25: SEIZ
A26: 5234871810 | B26: 7009321339 | C26: 44197.012 | D26: 200 W GARFIELD BLVD | E26: 60637 | F26: 9102020 | G26: RED LIGHT VIOLATION | H26: CNDT | I26: Red Light | J26: CNDT | K26: OTHR | L26: PAS | M26: 100 | N26: 200 | O26: 200 | P26: 0 | Q26: Notice | R26: 44210 | S26: SEIZ
A27: 5174922000 | B27: 7009321351 | C27: 44197.015 | D27: 800 W 99TH ST | E27: 60649 | F27: 9102020 | G27: RED LIGHT VIOLATION | H27: CNDT | I27: Red Light | J27: CNDT | K27: OTHR | L27: PAS | M27: 100 | N27: 200 | O27: 0 | P27: 100 | Q27: Paid | R27: 44356 | S27: DETR
A28: 5234871800 | B28: 7009321334 | C28: 44197.015 | D28: 4200 S CICERO AVENUE | E28: 470608002 | F28: 9102020 | G28: RED LIGHT VIOLATION | H28: CNDT | I28: Red Light | J28: CNDT | K28: OTHR | L28: PAS | M28: 100 | N28: 200 | O28: 0 | P28: 0 | Q28: Dismissed | R28: 44245 | S28: VIOL | T28: Not Liable | U28: Citizen was Not Owner or Lessee of Cited Vehicle
A29: 5232703710 | B29: 7009321405 | C29: 44197.015 | D29: 300 N HAMLIN AVENUE | E29: 60104 | F29: 9102020 | G29: RED LIGHT VIOLATION | H29: CNDT | I29: Red Light | J29: CNDT | K29: OTHR | L29: PAS | M29: 100 | N29: 200 | O29: 200 | P29: 0 | Q29: Notice | R29: 44210 | S29: SEIZ
A30: 0 | B30: 71748856 | C30: 44197.015 | D30: 453 N MCCLURG | F30: 0964080B | G30: NO STANDING/PARKING TIME RESTRICTED | H30: 495 | I30: Miscellaneous | J30: 371 | K30: MAZD | L30: HCP | M30: 100 | N30: 200 | O30: 100 | P30: 0 | Q30: Define | R30: 44235
A31: 5234915360 | B31: 7009325238 | C31: 44197.016 | D31: 3500 S WESTERN | E31: 60020 | F31: 9102020 | G31: RED LIGHT VIOLATION | H31: CNDT | I31: Red Light | J31: CNDT | K31: OTHR | L31: PAS | M31: 100 | N31: 200 | O31: 200 | P31: 0 | Q31: Notice | R31: 44210 | S31: FINL
A32: 5209732300 | B32: 7009321738 | C32: 44197.017 | D32: 2400 W MARQUETTE ROAD | E32: 605162270 | F32: 9102020 | G32: RED LIGHT VIOLATION | H32: CNDT | I32: Red Light | J32: CNDT | K32: OTHR | L32: PAS | M32: 100 | N32: 200 | O32: 200 | P32: 0 | Q32: Notice | R32: 44210 | S32: FINL
A33: 5234958860 | B33: 7009323433 | C33: 44197.017 | D33: 4000 N PULASKI ROAD | E33: 60707 | F33: 9102020 | G33: RED LIGHT VIOLATION | H33: CNDT | I33: Red Light | J33: CNDT | K33: OTHR | L33: PAS | M33: 100 | N33: 200 | O33: 200 | P33: 0 | Q33: Notice | R33: 44210 | S33: FINL
A34: 5234871840 | B34: 7009321373 | C34: 44197.017 | D34: 6700 S CORNELL DRIVE | E34: 60827 | F34: 9102020 | G34: RED LIGHT VIOLATION | H34: CNDT | I34: Red Light | J34: CNDT | K34: OTHR | L34: TMP | M34: 100 | N34: 200 | O34: 100 | P34: 0 | Q34: Court | R34: 44252 | S34: DETR
A35: 5234957950 | B35: 7009321365 | C35: 44197.017 | D35: 7600 S STONY ISLAND A | E35: 61832 | F35: 9102020 | G35: RED LIGHT VIOLATION | H35: CNDT | I35: Red Light | J35: CNDT | K35: OTHR | L35: PAS | M35: 100 | N35: 200 | O35: 200 | P35: 0 | Q35: Notice | R35: 44210 | S35: FINL
A36: 5234884190 | B36: 7009321737 | C36: 44197.017 | D36: 7600 S STONY ISLAND A | E36: 60643 | F36: 9102020 | G36: RED LIGHT VIOLATION | H36: CNDT | I36: Red Light | J36: CNDT | K36: OTHR | L36: PAS | M36: 100 | N36: 200 | O36: 200 | P36: 0 | Q36: Notice | R36: 44210 | S36: FINL
A37: 5234898520 | B37: 7009323423 | C37: 44197.018 | D37: 7100 S KEDZIE AVENUE | E37: 611153218 | F37: 9102020 | G37: RED LIGHT VIOLATION | H37: CNDT | I37: Red Light | J37: CNDT | K37: OTHR | L37: PAS | M37: 100 | N37: 200 | O37: 200 | P37: 0 | Q37: Notice | R37: 44295 | S37: FINL
A38: 5235458090 | B38: 71748876 | C38: 44197.019 | D38: 58 E HUBBARD | E38: 604091730 | F38: 0964080B | G38: NO STANDING/PARKING TIME RESTRICTED | H38: 495 | I38: Miscellaneous | J38: 375 | K38: CHEV | L38: PAS | M38: 100 | N38: 200 | O38: 0 | P38: 100 | Q38: Paid | R38: 44266 | S38: VIOL
A39: 5234915350 | B39: 7009325226 | C39: 44197.019 | D39: 3200 W 63RD ST | E39: 60804 | F39: 9102020 | G39: RED LIGHT VIOLATION | H39: CNDT | I39: Red Light | J39: CNDT | K39: OTHR | L39: PAS | M39: 100 | N39: 200 | O39: 200 | P39: 0 | Q39: Notice | R39: 44210 | S39: FINL
A40: 5234884180 | B40: 7009321734 | C40: 44197.022 | D40: 9500 S HALSTED STREET | E40: 604192968 | F40: 9102020 | G40: RED LIGHT VIOLATION | H40: CNDT | I40: Red Light | J40: CNDT | K40: OTHR | L40: PAS | M40: 100 | N40: 200 | O40: 200 | P40: 0 | Q40: Notice | R40: 44210 | S40: FINL
...

Sheet citations
A1: citation_id | B1: notice_number | C1: ticket_number | D1: violation_id | E1: unit_id | F1: officer_id | G1: license_plate_id | H1: fine_level1_id | I1: fine_level2_id | J1: notice_level_id
A2: 1 | B2: 5201586250 | C2: 7009321333 | D2: =_xlfn.XLOOKUP('Chicago Traffic Citations Data'!F2,violations!B:B,violations!A:A) -> 1 | E2: =_xlfn.XLOOKUP('Chicago Traffic Citations Data'!H2,units!B:B,units!A:A) -> 25 | F2: =_xlfn.XLOOKUP('Chicago Traffic Citations Data'!J2,officers!B:B,officers!A:A) -> 166 | G2: =_xlfn.XLOOKUP('Chicago Traffic Citations Data'!L2,license_plates!B:B,license_plates!A:A) -> 12 | H2: =_xlfn.XLOOKUP('Chicago Traffic Citations Data'!M2,fine_level_1!B:B,fine_level_1!A:A) -> 6 | I2: =_xlfn.XLOOKUP('Chicago Traffic Citations Data'!N2,fine_level_2!B:B,fine_level_2!A:A) -> 6 | J2: =_xlfn.XLOOKUP('Chicago Traffic Citations Data'!S2,notice_levels!B:B,notice_levels!A:A) -> 4
A3: 2 | B3: 5234871820 | C3: 7009321352 | D3: =_xlfn.XLOOKUP('Chicago Traffic Citations Data'!F3,violations!B:B,violations!A:A) -> 1 | E3: =_xlfn.XLOOKUP('Chicago Traffic Citations Data'!H3,units!B:B,units!A:A) -> 25 | F3: =_xlfn.XLOOKUP('Chicago Traffic Citations Data'!J3,officers!B:B,officers!A:A) -> 166 | G3: =_xlfn.XLOOKUP('Chicago Traffic Citations Data'!L3,license_plates!B:B,license_plates!A:A) -> 12 | H3: =_xlfn.XLOOKUP('Chicago Traffic Citations Data'!M3,fine_level_1!B:B,fine_level_1!A:A) -> 6 | I3: =_xlfn.XLOOKUP('Chicago Traffic Citations Data'!N3,fine_level_2!B:B,fine_level_2!A:A) -> 6 | J3: =_xlfn.XLOOKUP('Chicago Traffic Citations Data'!S3,notice_levels!B:B,notice_levels!A:A) -> 3
A4: 3 | B4: 5228076530 | C4: 72156572 | D4: =_xlfn.XLOOKUP('Chicago Traffic Citations Data'!F4,violations!B:B,violations!A:A) -> 5 | E4: =_xlfn.XLOOKUP('Chicago Traffic Citations Data'!H4,units!B:B,units!A:A) -> 1 | F4: =_xlfn.XLOOKUP('Chicago Traffic Citations Data'!J4,officers!B:B,officers!A:A) -> 56 | G4: =_xlfn.XLOOKUP('Chicago Traffic Citations Data'!L4,license_plates!B:B,license_plates!A:A) -> 12 | H4: =_xlfn.XLOOKUP('Chicago Traffic Citations Data'!M4,fine_level_1!B:B,fine_level_1!A:A) -> 6 | I4: =_xlfn.XLOOKUP('Chicago Traffic Citations Data'!N4,fine_level_2!B:B,fine_level_2!A:A) -> 6 | J4: =_xlfn.XLOOKUP('Chicago Traffic Citations Data'!S4,notice_levels!B:B,notice_levels!A:A) -> 5
A5: 4 | B5: 5233269710 | C5: 7009325236 | D5: =_xlfn.XLOOKUP('Chicago Traffic Citations Data'!F5,violations!B:B,violations!A:A) -> 1 | E5: =_xlfn.XLOOKUP('Chicago Traffic Citations Data'!H5,units!B:B,units!A:A) -> 25 | F5: =_xlfn.XLOOKUP('Chicago Traffic Citations Data'!J5,officers!B:B,officers!A:A) -> 166 | G5: =_xlfn.XLOOKUP('Chicago Traffic Citations Data'!L5,license_plates!B:B,license_plates!A:A) -> 12 | H5: =_xlfn.XLOOKUP('Chicago Traffic Citations Data'!M5,fine_level_1!B:B,fine_level_1!A:A) -> 6 | I5: =_xlfn.XLOOKUP('Chicago Traffic Citations Data'!N5,fine_level_2!B:B,fine_level_2!A:A) -> 6 | J5: =_xlfn.XLOOKUP('Chicago Traffic Citations Data'!S5,notice_levels!B:B,notice_levels!A:A) -> 3
A6: 5 | B6: 5219674400 | C6: 7009321372 | D6: =_xlfn.XLOOKUP('Chicago Traffic Citations Data'!F6,violations!B:B,violations!A:A) -> 1 | E6: =_xlfn.XLOOKUP('Chicago Traffic Citations Data'!H6,units!B:B,units!A:A) -> 25 | F6: =_xlfn.XLOOKUP('Chicago Traffic Citations Data'!J6,officers!B:B,officers!A:A) -> 166 | G6: =_xlfn.XLOOKUP('Chicago Traffic Citations Data'!L6,license_plates!B:B,license_plates!A:A) -> 12 | H6: =_xlfn.XLOOKUP('Chicago Traffic Citations Data'!M6,fine_level_1!B:B,fine_level_1!A:A) -> 6 | I6: =_xlfn.XLOOKUP('Chicago Traffic Citations Data'!N6,fine_level_2!B:B,fine_level_2!A:A) -> 6 | J6: =_xlfn.XLOOKUP('Chicago Traffic Citations Data'!S6,notice_levels!B:B,notice_levels!A:A) -> 4
A7: 6 | B7: 5199289380 | C7: 7009321329 | D7: =_xlfn.XLOOKUP('Chicago Traffic Citations Data'!F7,violations!B:B,violations!A:A) -> 1 | E7: =_xlfn.XLOOKUP('Chicago Traffic Citations Data'!H7,units!B:B,units!A:A) -> 25 | F7: =_xlfn.XLOOKUP('Chicago Traffic Citations Data'!J7,officers!B:B,officers!A:A) -> 166 | G7: =_xlfn.XLOOKUP('Chicago Traffic Citations Data'!L7,license_plates!B:B,license_plates!A:A) -> 12 | H7: =_xlfn.XLOOKUP('Chicago Traffic Citations Data'!M7,fine_level_1!B:B,fine_level_1!A:A) -> 6 | I7: =_xlfn.XLOOKUP('Chicago Traffic Citations Data'!N7,fine_level_2!B:B,fine_level_2!A:A) -> 6 | J7: =_xlfn.XLOOKUP('Chicago Traffic Citations Data'!S7,notice_levels!B:B,notice_levels!A:A) -> 4
A8: 7 | B8: 5225329540 | C8: 7009321376 | D8: =_xlfn.XLOOKUP('Chicago Traffic Citations Data'!F8,violations!B:B,violations!A:A) -> 1 | E8: =_xlfn.XLOOKUP('Chicago Traffic Citations Data'!H8,units!B:B,units!A:A) -> 25 | F8: =_xlfn.XLOOKUP('Chicago Traffic Citations Data'!J8,officers!B:B,officers!A:A) -> 166 | G8: =_xlfn.XLOOKUP('Chicago Traffic Citations Data'!L8,license_plates!B:B,license_plates!A:A) -> 12 | H8: =_xlfn.XLOOKUP('Chicago Traffic Citations Data'!M8,fine_level_1!B:B,fine_level_1!A:A) -> 6 | I8: =_xlfn.XLOOKUP('Chicago Traffic Citations Data'!N8,fine_level_2!B:B,fine_level_2!A:A) -> 6 | J8: =_xlfn.XLOOKUP('Chicago Traffic Citations Data'!S8,notice_levels!B:B,notice_levels!A:A) -> 1
A9: 8 | B9: 5212146160 | C9: 7009323424 | D9: =_xlfn.XLOOKUP('Chicago Traffic Citations Data'!F9,violations!B:B,violations!A:A) -> 1 | E9: =_xlfn.XLOOKUP('Chicago Traffic Citations Data'!H9,units!B:B,units!A:A) -> 25 | F9: =_xlfn.XLOOKUP('Chicago Traffic Citations Data'!J9,officers!B:B,officers!A:A) -> 166 | G9: =_xlfn.XLOOKUP('Chicago Traffic Citations Data'!L9,license_plates!B:B,license_plates!A:A) -> 12 | H9: =_xlfn.XLOOKUP('Chicago Traffic Citations Data'!M9,fine_level_1!B:B,fine_level_1!A:A) -> 6 | I9: =_xlfn.XLOOKUP('Chicago Traffic Citations Data'!N9,fine_level_2!B:B,fine_level_2!A:A) -> 6 | J9: =_xlfn.XLOOKUP('Chicago Traffic Citations Data'!S9,notice_levels!B:B,notice_levels!A:A) -> 5
A10: 9 | B10: 5235227160 | C10: 7009340321 | D10: =_xlfn.XLOOKUP('Chicago Traffic Citations Data'!F10,violations!B:B,violations!A:A) -> 1 | E10: =_xlfn.XLOOKUP('Chicago Traffic Citations Data'!H10,units!B:B,units!A:A) -> 25 | F10: =_xlfn.XLOOKUP('Chicago Traffic Citations Data'!J10,officers!B:B,officers!A:A) -> 166 | G10: =_xlfn.XLOOKUP('Chicago Traffic Citations Data'!L10,license_plates!B:B,license_plates!A:A) -> 12 | H10: =_xlfn.XLOOKUP('Chicago Traffic Citations Data'!M10,fine_level_1!B:B,fine_level_1!A:A) -> 6 | I10: =_xlfn.XLOOKUP('Chicago Traffic Citations Data'!N10,fine_level_2!B:B,fine_level_2!A:A) -> 6 | J10: =_xlfn.XLOOKUP('Chicago Traffic Citations Data'!S10,notice_levels!B:B,notice_levels!A:A) -> 3
A11: 10 | B11: 5210709690 | C11: 7009321419 | D11: =_xlfn.XLOOKUP('Chicago Traffic Citations Data'!F11,violations!B:B,violations!A:A) -> 1 | E11: =_xlfn.XLOOKUP('Chicago Traffic Citations Data'!H11,units!B:B,units!A:A) -> 25 | F11: =_xlfn.XLOOKUP('Chicago Traffic Citations Data'!J11,officers!B:B,officers!A:A) -> 166 | G11: =_xlfn.XLOOKUP('Chicago Traffic Citations Data'!L11,license_plates!B:B,license_plates!A:A) -> 12 | H11: =_xlfn.XLOOKUP('Chicago Traffic Citations Data'!M11,fine_level_1!B:B,fine_level_1!A:A) -> 6 | I11: =_xlfn.XLOOKUP('Chicago Traffic Citations Data'!N11,fine_level_2!B:B,fine_level_2!A:A) -> 6 | J11: =_xlfn.XLOOKUP('Chicago Traffic Citations Data'!S11,notice_levels!B:B,notice_levels!A:A) -> 3
A12: 11 | B12: 5231657240 | C12: 7009321728 | D12: =_xlfn.XLOOKUP('Chicago Traffic Citations Data'!F12,violations!B:B,violations!A:A) -> 1 | E12: =_xlfn.XLOOKUP('Chicago Traffic Citations Data'!H12,units!B:B,units!A:A) -> 25 | F12: =_xlfn.XLOOKUP('Chicago Traffic Citations Data'!J12,officers!B:B,officers!A:A) -> 166 | G12: =_xlfn.XLOOKUP('Chicago Traffic Citations Data'!L12,license_plates!B:B,license_plates!A:A) -> 12 | H12: =_xlfn.XLOOKUP('Chicago Traffic Citations Data'!M12,fine_level_1!B:B,fine_level_1!A:A) -> 6 | I12: =_xlfn.XLOOKUP('Chicago Traffic Citations Data'!N12,fine_level_2!B:B,fine_level_2!A:A) -> 6 | J12: =_xlfn.XLOOKUP('Chicago Traffic Citations Data'!S12,notice_levels!B:B,notice_levels!A:A) -> 3
A13: 12 | B13: 5146642870 | C13: 72156573 | D13: =_xlfn.XLOOKUP('Chicago Traffic Citations Data'!F13,violations!B:B,violations!A:A) -> 5 | E13: =_xlfn.XLOOKUP('Chicago Traffic Citations Data'!H13,units!B:B,units!A:A) -> 1 | F13: =_xlfn.XLOOKUP('Chicago Traffic Citations Data'!J13,officers!B:B,officers!A:A) -> 56 | G13: =_xlfn.XLOOKUP('Chicago Traffic Citations Data'!L13,license_plates!B:B,license_plates!A:A) -> 12 | H13: =_xlfn.XLOOKUP('Chicago Traffic Citations Data'!M13,fine_level_1!B:B,fine_level_1!A:A) -> 6 | I13: =_xlfn.XLOOKUP('Chicago Traffic Citations Data'!N13,fine_level_2!B:B,fine_level_2!A:A) -> 6 | J13: =_xlfn.XLOOKUP('Chicago Traffic Citations Data'!S13,notice_levels!B:B,notice_levels!A:A) -> 1
... A1993: 1992 | B1993: 5227431080 | C1993: 6048485275 | D1993: =_xlfn.XLOOKUP('Chicago Traffic Citations Data'!F1993,violations!B:B,violations!A:A) -> 25 | E1993: =_xlfn.XLOOKUP('Chicago Traffic Citations Data'!H1993,units!B:B,units!A:A) -> 26 | F1993: =_xlfn.XLOOKUP('Chicago Traffic Citations Data'!J1993,officers!B:B,officers!A:A) -> 167 | G1993: =_xlfn.XLOOKUP('Chicago Traffic Citations Data'!L1993,license_plates!B:B,license_plates!A:A) -> 12 | H1993: =_xlfn.XLOOKUP('Chicago Traffic Citations Data'!M1993,fine_level_1!B:B,fine_level_1!A:A) -> 6 | I1993: =_xlfn.XLOOKUP('Chicago Traffic Citations Data'!N1993,fine_level_2!B:B,fine_level_2!A:A) -> 6 | J1993: =_xlfn.XLOOKUP('Chicago Traffic Citations Data'!S1993,notice_levels!B:B,notice_levels!A:A) -> 3

Sheet violations
A1: violation_id | B1: violation_code | C1: violation_description
A2: 1 | B2: 9102020 | C2: RED LIGHT VIOLATION
A3: 2 | B3: 0964020A | C3: WRONG DIRECTION OR 12'' FROM CURB
A4: 3 | B4: 0964050J | C4: DISABLED PARKING ZONE
A5: 4 | B5: 0964080A | C5: RUSH HOUR PARKING
A6: 5 | B6: 0964080B | C6: NO STANDING/PARKING TIME RESTRICTED
A7: 6 | B7: 0964090E | C7: RESIDENTIAL PERMIT PARKING
A8: 7 | B8: 0964100A | C8: WITHIN 15' OF FIRE HYDRANT
A9: 8 | B9: 0964100C | C9: BLOCK ACCESS/ALLEY/DRIVEWAY/FIRELANE
A10: 9 | B10: 0964100G | C10: STOP SIGN OR TRAFFIC SIGNAL
A11: 10 | B11: 0964110A1 | C11: DOUBLE PARKING/STANDING NON-CENTRAL BUSINESS DISTR
A12: 11 | B12: 0964110A2 | C12: DOUBLE PARKING/STANDING CENTRAL BUSINESS DISTRICT
A13: 12 | B13: 0964110C | C13: PARK OR STAND ON CROSSWALK
A14: 13 | B14: 0964110D | C14: PARK OR STAND ON SIDEWALK
... A26: 25 | B26: 9101020** | C26: SPEED VIOLATION 11+

Sheet license_plates
A1: license_plate_id | B1: license_plate_type
A2: 1 | B2: BRS
A3: 2 | B3: BUL
A4: 3 | B4: CBK
A5: 4 | B5: CUB
A6: 5 | B6: DLC
A7: 6 | B7: DOM
A8: 7 | B8: ELE
A9: 8 | B9: FFM
A10: 9 | B10: HCP
A11: 10 | B11: IPN
A12: 11 | B12: LIV
A13: 12 | B13: PAS
... A19: 18 | B19: TXI

Sheet fine_level_1
A1: fine_level1_id | B1: fine_level1_amount
A2: 1 | B2: 0
A3: 2 | B3: 25
A4: 3 | B4: 35
A5: 4 | B5: 60
A6: 5 | B6: 75
A7: 6 | B7: 100
A8: 7 | B8: 150
A9: 8 | B9: 200
A10: 9 | B10: 250
A11: 10 | B11: 300

Sheet fine_level_2
A1: fine_level2_id | B1: fine_level2_amount
A2: 1 | B2: 0
A3: 2 | B3: 50
A4: 3 | B4: 70
A5: 4 | B5: 120
A6: 5 | B6: 150
A7: 6 | B7: 200
A8: 7 | B8: 250
A9: 8 | B9: 300
A10: 9 | B10: 500
A11: 10 | B11: 600

Sheet notice_levels
A1: notice_level_id | B1: notice_level
A2: 1 | B2: DETR
A3: 2 | B3: DLS
A4: 3 | B4: FINL
A5: 4 | B5: SEIZ
A6: 5 | B6: VIOL
A7: 6

Sheet vehicle_locations
A1: citation_id | B1: location_id | C1: vehicle_id | D1: issue_date
A2: 1 | B2: =_xlfn.XLOOKUP('Chicago Traffic Citations Data'!E2,locations!C:C,locations!A:A) -> 1359 | C2: =_xlfn.XLOOKUP('Chicago Traffic Citations Data'!K2,vehicles!B:B,vehicles!A:A) -> 26 | D2: 44197
A3: 2 | B3: =_xlfn.XLOOKUP('Chicago Traffic Citations Data'!E3,locations!C:C,locations!A:A) -> 1512 | C3: =_xlfn.XLOOKUP('Chicago Traffic Citations Data'!K3,vehicles!B:B,vehicles!A:A) -> 26 | D3: 44197
A4: 3 | B4: =_xlfn.XLOOKUP('Chicago Traffic Citations Data'!E4,locations!C:C,locations!A:A) -> 1792 | C4: =_xlfn.XLOOKUP('Chicago Traffic Citations Data'!K4,vehicles!B:B,vehicles!A:A) -> 4 | D4: 44197.001
A5: 4 | B5: =_xlfn.XLOOKUP('Chicago Traffic Citations Data'!E5,locations!C:C,locations!A:A) -> 275 | C5: =_xlfn.XLOOKUP('Chicago Traffic Citations Data'!K5,vehicles!B:B,vehicles!A:A) -> 26 | D5: 44197.001
A6: 5 | B6: =_xlfn.XLOOKUP('Chicago Traffic Citations Data'!E6,locations!C:C,locations!A:A) -> 1560 | C6: =_xlfn.XLOOKUP('Chicago Traffic Citations Data'!K6,vehicles!B:B,vehicles!A:A) -> 26 | D6: 44197.001
A7: 6 | B7: =_xlfn.XLOOKUP('Chicago Traffic Citations Data'!E7,locations!C:C,locations!A:A) -> 495 | C7: =_xlfn.XLOOKUP('Chicago Traffic Citations Data'!K7,vehicles!B:B,vehicles!A:A) -> 26 | D7: 44197.001
A8: 7 | B8: =_xlfn.XLOOKUP('Chicago Traffic Citations Data'!E8,locations!C:C,locations!A:A) -> 904 | C8: =_xlfn.XLOOKUP('Chicago Traffic Citations Data'!K8,vehicles!B:B,vehicles!A:A) -> 26 | D8: 44197.001
A9: 8 | B9: =_xlfn.XLOOKUP('Chicago Traffic Citations Data'!E9,locations!C:C,locations!A:A) -> 1084 | C9: =_xlfn.XLOOKUP('Chicago Traffic Citations Data'!K9,vehicles!B:B,vehicles!A:A) -> 26 | D9: 44197.001
A10: 9 | B10: =_xlfn.XLOOKUP('Chicago Traffic Citations Data'!E10,locations!C:C,locations!A:A) -> 225 | C10: =_xlfn.XLOOKUP('Chicago Traffic Citations Data'!K10,vehicles!B:B,vehicles!A:A) -> 26 | D10: 44197.002
A11: 10 | B11: =_xlfn.XLOOKUP('Chicago Traffic Citations Data'!E11,locations!C:C,locations!A:A) -> 803 | C11: =_xlfn.XLOOKUP('Chicago Traffic Citations Data'!K11,vehicles!B:B,vehicles!A:A) -> 26 | D11: 44197.004
A12: 11 | B12: =_xlfn.XLOOKUP('Chicago Traffic Citations Data'!E12,locations!C:C,locations!A:A) -> 240 | C12: =_xlfn.XLOOKUP('Chicago Traffic Citations Data'!K12,vehicles!B:B,vehicles!A:A) -> 26 | D12: 44197.005
A13: 12 | B13: =_xlfn.XLOOKUP('Chicago Traffic Citations Data'!E13,locations!C:C,locations!A:A) -> 1024 | C13: =_xlfn.XLOOKUP('Chicago Traffic Citations Data'!K13,vehicles!B:B,vehicles!A:A) -> 18 | D13: 44197.006
... A1993: 1992 | B1993: =_xlfn.XLOOKUP('Chicago Traffic Citations Data'!E1993,locations!C:C,locations!A:A) -> 1257 | C1993: =_xlfn.XLOOKUP('Chicago Traffic Citations Data'!K1993,vehicles!B:B,vehicles!A:A) -> 26 | D1993: 44197.603

Sheet locations
A1: location_id | B1: violation_location | C1: zip_code
A2: 1 | B2: 3956 N CENTRAL | C2: 20772
A3: 2 | B3: 30 W 87TH STREET | C3: 37166
A4: 3 | B4: 1334 W GARFIELD BLVD | C4: 38118
A5: 4 | B5: 1901 E 75TH ST | C5: 38344
A6: 5 | B6: 10318 S INDIANAPOLIS | C6: 38821
A7: 6 | B7: 1200 S CANAL STREET | C7: 40242
A8: 7 | B8: 5 W TERMINAL ST | C8: 45238
A9: 8 | B9: 142 E ONTARIO | C9: 46307
A10: 9 | B10: 7900 S STATE STREET | C10: 46312
A11: 10 | B11: 449 N COLUMBUS DR | C11: 46321
A12: 11 | B12: 10318 S INDIANAPOLIS | C12: 46410
A13: 12 | B13: 100 W CHICAGO AVENUE | C13: 48111
... A1924: 1923 | B1924: 3137 W PETERSON | C1924: 981072344
A1925: 1924 | B1925: 1542 W BIRCHWOOD
A1926: 1925 | B1926: 453 N MCCLURG
A1927: 1926 | B1927: 90 E 46TH STREET
A1928: 1927 | B1928: 220 W ERIE ST
A1929: 1928 | B1929: 21 E HUBBARD
A1930: 1929 | B1930: 665 W ALDINE AV
A1931: 1930 | B1931: 203 S COLUMBUS DR
A1932: 1931 | B1932: 11110 S HALE
A1933: 1932 | B1933: 254 E WALTON
A1934: 1933 | B1934: 252 E WALTON
A1935: 1934 | B1935: 250 E WALTON
A1936: 1935 | B1936: 248 E WALTON
... A1993: 1992 | B1993: 900 N MICHIGAN

Sheet vehicles
A1: vehicle_id | B1: vehicle_make
A2: 1 | B2: ACUR
A3: 2 | B3: ALFA
A4: 3 | B4: AUDI
A5: 4 | B5: BMW
A6: 5 | B6: BUIC
A7: 6 | B7: CADI
A8: 7 | B8: CHEV
A9: 8 | B9: CHRY
A10: 9 | B10: DODG
A11: 10 | B11: FORD
A12: 11 | B12: GMC
A13: 12 | B13: HOND
... A35: 34 | B35: VOLV

Sheet units
A1: unit_id | B1: unit_number
A2: 1 | B2: 1
A3: 2 | B3: 2
A4: 3 | B4: 3
A5: 4 | B5: 4
A6: 5 | B6: 5
A7: 6 | B7: 6
A8: 7 | B8: 7
A9: 8 | B9: 8
A10: 9 | B10: 9
A11: 10 | B11: 10
A12: 11 | B12: 11
A13: 12 | B13: 12
... A25: 24 | B25: 716
A26: 25 | B26: CNDT
A27: 26 | B27: SPD

Sheet officers
A1: officer_id | B1: officer
A2: 1 | B2: 319
A3: 2 | B3: 371
A4: 3 | B4: 375
A5: 4 | B5: 376
A6: 5 | B6: 494
A7: 6 | B7: 1170
A8: 7 | B8: 1717
A9: 8 | B9: 1939
A10: 9 | B10: 2822
A11: 10 | B11: 2920
A12: 11 | B12: 2950
A13: 12 | B13: 3051
... A166: 165 | B166: 19880
A167: 166 | B167: CNDT
A168: 167 | B168: SPEED
